Workbook

Sheet Colores
A1: HEX | B1: R | C1: G | D1: B | E1: Color
A2: #ee6261 | B2: 238 | C2: 98 | D2: 97
A3: #f3a960 | B3: 243 | C3: 169 | D3: 96
A4: #1e5b78 | B4: 30 | C4: 91 | D4: 120
A5: #164a60 | B5: 22 | C5: 74 | D5: 96
A6: #468a97 | B6: 70 | C6: 138 | D6: 151

Sheet Síntesis
A3: Empleo (mes) | E3: Empleo (abril)
A4: Privado | B4: ='T.2.2'!L180/1000 -> -9.059 | E4: Privado | F4: ='T.2.2'!R180/1000 -> -2.1152276e-06
A5: Público | B5: ='T.2.2'!M180/1000 -> 0.736 | E5: Público | F5: ='T.2.2'!S180/1000 -> -323.984
A6: Casas particulares | B6: ='T.2.2'!N180/1000 -> 1.352 | E6: Casas particulares | F6: ='T.2.2'!T180/1000 -> -3.1321731e-05
A7: Total | B7: ='T.2.2'!K180/1000 -> -6.971 | E7: Total | F7: ='T.2.2'!Q180/1000 -> -21.239
A9: Salario mínimo (mes) | B9: -0.005 | E9: Salario mínimo (junio) | F9: 0.001
A11: Salario promedio (mes) | B11: =A.4!L202 -> 0.0060678594 | E11: Salario promedio (abril) | F11: =A.4!R199 -> 0
A14: Empleo (abril)
A15: Privado | B15: ='T.2.2'!L180 -> -9059
A16: Público | B16: ='T.2.2'!M180 -> 736
A17: Casas particulares | B17: ='T.2.2'!N180 -> 1352
A18: Total | B18: ='T.2.2'!K180 -> -6971
A20: Salario mínimo (junio) | B20: 0.001
A22: Salario promedio (abril) | B22: =A.4!L199 -> -0.020910365

Sheet T.2.2
A1: Personas con trabajo registrado según modalidad ocupacional principal. Sin estacionalidad | Q1: Asalariados totales | V1: Asalariados privados | AA1: Asalariados públicos | AF1: Asalariados de casas particulares
A2: Período | B2: Empleo asalariado en el sector privado | C2: Empleo asalariado en el sector público | D2: Empleo en casas particulares | E2: Trabajo Independientes Autónomos | F2: Trabajo Independientes Monotributo | G2: Trabajo Independientes Monotributo Social | H2: Total | K2: Total asalariados | L2: Asalariados privados | M2: Asalariados públicos | N2: Casas particulares | O2: No asalariados | Q2: Var. Mensual absoluta | R2: Var. Mensual % | S2: Var. Mensual respecto max abs () | T2: Var. Mensual respecto max % | V2: Var. Mensual absoluta | W2: Var. Mensual % | X2: Var. Mensual respecto max abs () | Y2: Var. Mensual respecto max % | AA2: Var. Mensual absoluta | AB2: Var. Mensual % | AC2: Var. Mensual respecto max abs () | AD2: Var. Mensual respecto max % | AF2: Var. Mensual absoluta | AG2: Var. Mensual % | AH2: Var. Mensual respecto max abs () | AI2: Var. Mensual respecto max %
A3: 40909 | B3: 6068.216 | C3: 2549.861 | D3: 389.749 | E3: 408.233 | F3: 1314.711 | G3: 167.762 | H3: =+SUM(B3:G3) -> 10898.532 | J3: =A3 -> 40909 | K3: =B3+C3+D3 -> 9007.826 | L3: =B3 -> 6068.216 | M3: =C3 -> 2549.861 | N3: =D3 -> 389.749 | O3: =E3+F3+G3 -> 1890.706
A4: 40940 | B4: 6062.094 | C4: 2610.443 | D4: 390.329 | E4: 408.144 | F4: 1314.532 | G4: 168.913 | H4: =+SUM(B4:G4) -> 10954.455 | J4: =A4 -> 40940 | K4: =B4+C4+D4 -> 9062.866 | L4: =B4 -> 6062.094 | M4: =C4 -> 2610.443 | N4: =D4 -> 390.329 | O4: =E4+F4+G4 -> 1891.589 | Q4: =(K4-K3)*1000 -> 55040 | R4: =K4/K3-1 -> 0.0061102424 | V4: =(L4-L3)*1000 -> -6122 | W4: =L4/L3-1 -> -0.0010088632 | AA4: =(M4-M3)*1000 -> 60582 | AB4: =M4/M3-1 -> 0.023758942 | AF4: =(N4-N3)*1000 -> 580 | AG4: =N4/N3-1 -> 0.0014881372
A5: 40969 | B5: 6072.366 | C5: 2622.473 | D5: 390.324 | E5: 407.754 | F5: 1314.626 | G5: 170.047 | H5: =+SUM(B5:G5) -> 10977.59 | J5: =A5 -> 40969 | K5: =B5+C5+D5 -> 9085.163 | L5: =B5 -> 6072.366 | M5: =C5 -> 2622.473 | N5: =D5 -> 390.324 | O5: =E5+F5+G5 -> 1892.427 | Q5: =(K5-K4)*1000 -> 22297 | R5: =K5/K4-1 -> 0.0024602593 | V5: =(L5-L4)*1000 -> 10272 | W5: =L5/L4-1 -> 0.001694464 | AA5: =(M5-M4)*1000 -> 12030 | AB5: =M5/M4-1 -> 0.0046084132 | AF5: =(N5-N4)*1000 -> -5 | AG5: =N5/N4-1 -> -1.2809707e-05
A6: 41000 | B6: 6055.303 | C6: 2625.352 | D6: 391.723 | E6: 408.092 | F6: 1317.796 | G6: 172.512 | H6: =+SUM(B6:G6) -> 10970.778 | J6: =A6 -> 41000 | K6: =B6+C6+D6 -> 9072.378 | L6: =B6 -> 6055.303 | M6: =C6 -> 2625.352 | N6: =D6 -> 391.723 | O6: =E6+F6+G6 -> 1898.4 | Q6: =(K6-K5)*1000 -> -12785 | R6: =K6/K5-1 -> -0.0014072395 | V6: =(L6-L5)*1000 -> -17063 | W6: =L6/L5-1 -> -0.0028099426 | AA6: =(M6-M5)*1000 -> 2879 | AB6: =M6/M5-1 -> 0.0010978187 | AF6: =(N6-N5)*1000 -> 1399 | AG6: =N6/N5-1 -> 0.0035842018
A7: 41030 | B7: 6065.665 | C7: 2597.908 | D7: 393.058 | E7: 408.112 | F7: 1321.841 | G7: 172.926 | H7: =+SUM(B7:G7) -> 10959.51 | J7: =A7 -> 41030 | K7: =B7+C7+D7 -> 9056.631 | L7: =B7 -> 6065.665 | M7: =C7 -> 2597.908 | N7: =D7 -> 393.058 | O7: =E7+F7+G7 -> 1902.879 | Q7: =(K7-K6)*1000 -> -15747 | R7: =K7/K6-1 -> -0.0017357081 | V7: =(L7-L6)*1000 -> 10362 | W7: =L7/L6-1 -> 0.0017112273 | AA7: =(M7-M6)*1000 -> -27444 | AB7: =M7/M6-1 -> -0.010453455 | AF7: =(N7-N6)*1000 -> 1335 | AG7: =N7/N6-1 -> 0.0034080205
A8: 41061 | B8: 6065.234 | C8: 2632.424 | D8: 394.674 | E8: 408.661 | F8: 1332.556 | G8: 174.563 | H8: =+SUM(B8:G8) -> 11008.112 | J8: =A8 -> 41061 | K8: =B8+C8+D8 -> 9092.332 | L8: =B8 -> 6065.234 | M8: =C8 -> 2632.424 | N8: =D8 -> 394.674 | O8: =E8+F8+G8 -> 1915.78 | Q8: =(K8-K7)*1000 -> 35701 | R8: =K8/K7-1 -> 0.0039419736 | V8: =(L8-L7)*1000 -> -431 | W8: =L8/L7-1 -> -7.1055688e-05 | AA8: =(M8-M7)*1000 -> 34516 | AB8: =M8/M7-1 -> 0.013286075 | AF8: =(N8-N7)*1000 -> 1616 | AG8: =N8/N7-1 -> 0.0041113525
A9: 41091 | B9: 6063.151 | C9: 2628.807 | D9: 395.905 | E9: 408.636 | F9: 1342.079 | G9: 178.134 | H9: =+SUM(B9:G9) -> 11016.712 | J9: =A9 -> 41091 | K9: =B9+C9+D9 -> 9087.863 | L9: =B9 -> 6063.151 | M9: =C9 -> 2628.807 | N9: =D9 -> 395.905 | O9: =E9+F9+G9 -> 1928.849 | Q9: =(K9-K8)*1000 -> -4469 | R9: =K9/K8-1 -> -0.00049151307 | V9: =(L9-L8)*1000 -> -2083 | W9: =L9/L8-1 -> -0.00034343275 | AA9: =(M9-M8)*1000 -> -3617 | AB9: =M9/M8-1 -> -0.0013740188 | AF9: =(N9-N8)*1000 -> 1231 | AG9: =N9/N8-1 -> 0.0031190299
A10: 41122 | B10: 6059.961 | C10: 2636.891 | D10: 397.548 | E10: 408.273 | F10: 1346.925 | G10: 179.842 | H10: =+SUM(B10:G10) -> 11029.44 | J10: =A10 -> 41122 | K10: =B10+C10+D10 -> 9094.4 | L10: =B10 -> 6059.961 | M10: =C10 -> 2636.891 | N10: =D10 -> 397.548 | O10: =E10+F10+G10 -> 1935.04 | Q10: =(K10-K9)*1000 -> 6537 | R10: =K10/K9-1 -> 0.00071931102 | V10: =(L10-L9)*1000 -> -3190 | W10: =L10/L9-1 -> -0.00052612907 | AA10: =(M10-M9)*1000 -> 8084 | AB10: =M10/M9-1 -> 0.0030751592 | AF10: =(N10-N9)*1000 -> 1643 | AG10: =N10/N9-1 -> 0.0041499855
A11: 41153 | B11: 6058.538 | C11: 2632.422 | D11: 398.647 | E11: 408.255 | F11: 1352.378 | G11: 182.364 | H11: =+SUM(B11:G11) -> 11032.604 | J11: =A11 -> 41153 | K11: =B11+C11+D11 -> 9089.607 | L11: =B11 -> 6058.538 | M11: =C11 -> 2632.422 | N11: =D11 -> 398.647 | O11: =E11+F11+G11 -> 1942.997 | Q11: =(K11-K10)*1000 -> -4793 | R11: =K11/K10-1 -> -0.00052702762 | V11: =(L11-L10)*1000 -> -1423 | W11: =L11/L10-1 -> -0.00023481999 | AA11: =(M11-M10)*1000 -> -4469 | AB11: =M11/M10-1 -> -0.0016947989 | AF11: =(N11-N10)*1000 -> 1099 | AG11: =N11/N10-1 -> 0.0027644461
A12: 41183 | B12: 6063.41 | C12: 2640.629 | D12: 399.694 | E12: 408.282 | F12: 1360.189 | G12: 183.254 | H12: =+SUM(B12:G12) -> 11055.458 | J12: =A12 -> 41183 | K12: =B12+C12+D12 -> 9103.733 | L12: =B12 -> 6063.41 | M12: =C12 -> 2640.629 | N12: =D12 -> 399.694 | O12: =E12+F12+G12 -> 1951.725 | Q12: =(K12-K11)*1000 -> 14126 | R12: =K12/K11-1 -> 0.0015540826 | V12: =(L12-L11)*1000 -> 4872 | W12: =L12/L11-1 -> 0.0008041544 | AA12: =(M12-M11)*1000 -> 8207 | AB12: =M12/M11-1 -> 0.0031176612 | AF12: =(N12-N11)*1000 -> 1047 | AG12: =N12/N11-1 -> 0.0026263837
A13: 41214 | B13: 6068.999 | C13: 2655.904 | D13: 401.083 | E13: 408.979 | F13: 1365.476 | G13: 184.774 | H13: =+SUM(B13:G13) -> 11085.215 | J13: =A13 -> 41214 | K13: =B13+C13+D13 -> 9125.986 | L13: =B13 -> 6068.999 | M13: =C13 -> 2655.904 | N13: =D13 -> 401.083 | O13: =E13+F13+G13 -> 1959.229 | Q13: =(K13-K12)*1000 -> 22253 | R13: =K13/K12-1 -> 0.0024443819 | V13: =(L13-L12)*1000 -> 5589 | W13: =L13/L12-1 -> 0.00092175855 | AA13: =(M13-M12)*1000 -> 15275 | AB13: =M13/M12-1 -> 0.0057846066 | AF13: =(N13-N12)*1000 -> 1389 | AG13: =N13/N12-1 -> 0.0034751585
A14: 41244 | B14: 6090.752 | C14: 2658.476 | D14: 402.216 | E14: 409.964 | F14: 1364.714 | G14: 186.953 | H14: =+SUM(B14:G14) -> 11113.075 | J14: =A14 -> 41244 | K14: =B14+C14+D14 -> 9151.444 | L14: =B14 -> 6090.752 | M14: =C14 -> 2658.476 | N14: =D14 -> 402.216 | O14: =E14+F14+G14 -> 1961.631 | Q14: =(K14-K13)*1000 -> 25458 | R14: =K14/K13-1 -> 0.0027896164 | V14: =(L14-L13)*1000 -> 21753 | W14: =L14/L13-1 -> 0.0035842814 | AA14: =(M14-M13)*1000 -> 2572 | AB14: =M14/M13-1 -> 0.0009684085 | AF14: =(N14-N13)*1000 -> 1133 | AG14: =N14/N13-1 -> 0.0028248517
A15: 41275 | B15: 6090.41 | C15: 2714.192 | D15: 407.944 | E15: 411.077 | F15: 1370.088 | G15: 187.364 | H15: =+SUM(B15:G15) -> 11181.075 | J15: =A15 -> 41275 | K15: =B15+C15+D15 -> 9212.546 | L15: =B15 -> 6090.41 | M15: =C15 -> 2714.192 | N15: =D15 -> 407.944 | O15: =E15+F15+G15 -> 1968.529 | Q15: =(K15-K14)*1000 -> 61102 | R15: =K15/K14-1 -> 0.0066767605 | V15: =(L15-L14)*1000 -> -342 | W15: =L15/L14-1 -> -5.6150702e-05 | AA15: =(M15-M14)*1000 -> 55716 | AB15: =M15/M14-1 -> 0.020957872 | AF15: =(N15-N14)*1000 -> 5728 | AG15: =N15/N14-1 -> 0.014241104
... A141: 45108 | B141: 6404.813 | C141: 3458.199 | D141: 467.962 | E141: 407.324 | F141: 1984.376 | G141: 612.028 | H141: =+SUM(B141:G141) -> 13334.702 | J141: =A141 -> 45108 | K141: =B141+C141+D141 -> 10330.974 | L141: =B141 -> 6404.813 | M141: =C141 -> 3458.199 | N141: =D141 -> 467.962 | O141: =E141+F141+G141 -> 3003.728 | Q141: =(K141-K140)*1000 -> 26126 | R141: =K141/K140-1 -> 0.0025353115 | V141: =(L141-L140)*1000 -> 18751 | W141: =L141/L140-1 -> 0.0029362383 | AA141: =(M141-M140)*1000 -> 7261 | AB141: =M141/M140-1 -> 0.0021040656 | AF141: =(N141-N140)*1000 -> 114 | AG141: =N141/N140-1 -> 0.00024366888
A142: 45139 | B142: 6408.136 | C142: 3467.835 | D142: 467.774 | E142: 409.266 | F142: 2017.037 | G142: 594.985 | H142: =+SUM(B142:G142) -> 13365.033 | J142: =A142 -> 45139 | K142: =B142+C142+D142 -> 10343.745 | L142: =B142 -> 6408.136 | M142: =C142 -> 3467.835 | N142: =D142 -> 467.774 | O142: =E142+F142+G142 -> 3021.288 | Q142: =(K142-K141)*1000 -> 12771 | R142: =K142/K141-1 -> 0.0012361855 | S142: =(K142-$K$142)*1000 -> 0 | T142: =K142/$K$142-1 -> 0 | V142: =(L142-L141)*1000 -> 3323 | W142: =L142/L141-1 -> 0.00051882857 | X142: =(L142-$L$142)*1000 -> 0 | Y142: =L142/$L$142-1 -> 0 | AA142: =(M142-M141)*1000 -> 9636 | AB142: =M142/M141-1 -> 0.0027864215 | AF142: =(N142-N141)*1000 -> -188 | AG142: =N142/N141-1 -> -0.00040174202
A143: 45170 | B143: 6393.259 | C143: 3466.33 | D143: 468.056 | E143: 410.947 | F143: 2010.057 | G143: 623.271 | H143: =+SUM(B143:G143) -> 13371.92 | J143: =A143 -> 45170 | K143: =B143+C143+D143 -> 10327.645 | L143: =B143 -> 6393.259 | M143: =C143 -> 3466.33 | N143: =D143 -> 468.056 | O143: =E143+F143+G143 -> 3044.275 | Q143: =(K143-K142)*1000 -> -16100 | R143: =K143/K142-1 -> -0.0015564962 | S143: =(K143-$K$142)*1000 -> -16100 | T143: =K143/$K$142-1 -> -0.0015564962 | V143: =(L143-L142)*1000 -> -14877 | W143: =L143/L142-1 -> -0.0023215799 | X143: =(L143-$L$142)*1000 -> -14877 | Y143: =L143/$L$142-1 -> -0.0023215799 | AA143: =(M143-M142)*1000 -> -1505 | AB143: =M143/M142-1 -> -0.00043398835 | AF143: =(N143-N142)*1000 -> 282 | AG143: =N143/N142-1 -> 0.00060285522
A144: 45200 | B144: 6380.831 | C144: 3467.948 | D144: 466.505 | E144: 410.553 | F144: 2042.447 | G144: 605.915 | H144: =+SUM(B144:G144) -> 13374.199 | J144: =A144 -> 45200 | K144: =B144+C144+D144 -> 10315.284 | L144: =B144 -> 6380.831 | M144: =C144 -> 3467.948 | N144: =D144 -> 466.505 | O144: =E144+F144+G144 -> 3058.915 | Q144: =(K144-K143)*1000 -> -12361 | R144: =K144/K143-1 -> -0.0011968847 | S144: =(K144-$K$142)*1000 -> -28461 | T144: =K144/$K$142-1 -> -0.0027515179 | V144: =(L144-L143)*1000 -> -12428 | W144: =L144/L143-1 -> -0.0019439225 | X144: =(L144-$L$142)*1000 -> -27305 | Y144: =L144/$L$142-1 -> -0.0042609895 | AA144: =(M144-M143)*1000 -> 1618 | AB144: =M144/M143-1 -> 0.0004667761 | AF144: =(N144-N143)*1000 -> -1551 | AG144: =N144/N143-1 -> -0.0033137061
A145: 45231 | B145: 6372.697 | C145: 3467.374 | D145: 464.279 | E145: 388.327 | F145: 2037.762 | G145: 634.72 | H145: =+SUM(B145:G145) -> 13365.159 | J145: =A145 -> 45231 | K145: =B145+C145+D145 -> 10304.35 | L145: =B145 -> 6372.697 | M145: =C145 -> 3467.374 | N145: =D145 -> 464.279 | O145: =E145+F145+G145 -> 3060.809 | Q145: =(K145-K144)*1000 -> -10934 | R145: =K145/K144-1 -> -0.0010599805 | S145: =(K145-$K$142)*1000 -> -39395 | T145: =K145/$K$142-1 -> -0.0038085819 | V145: =(L145-L144)*1000 -> -8134 | W145: =L145/L144-1 -> -0.0012747556 | X145: =(L145-$L$142)*1000 -> -35439 | Y145: =L145/$L$142-1 -> -0.0055303133 | AA145: =(M145-M144)*1000 -> -574 | AB145: =M145/M144-1 -> -0.00016551575 | AF145: =(N145-N144)*1000 -> -2226 | AG145: =N145/N144-1 -> -0.004771653 | AH145: =(N145-$N$177)*1000 -> -35964
A146: 45261 | B146: 6361.318 | C146: 3474.461 | D146: 462.01 | E146: 383.692 | F146: 2044.814 | G146: 637.406 | H146: =+SUM(B146:G146) -> 13363.701 | J146: =A146 -> 45261 | K146: =B146+C146+D146 -> 10297.789 | L146: =B146 -> 6361.318 | M146: =C146 -> 3474.461 | N146: =D146 -> 462.01 | O146: =E146+F146+G146 -> 3065.912 | Q146: =(K146-K145)*1000 -> -6561 | R146: =K146/K145-1 -> -0.00063672138 | S146: =(K146-$K$142)*1000 -> -45956 | T146: =K146/$K$142-1 -> -0.0044428783 | V146: =(L146-L145)*1000 -> -11379 | W146: =L146/L145-1 -> -0.0017855862 | X146: =(L146-$L$142)*1000 -> -46818 | Y146: =L146/$L$142-1 -> -0.0073060247 | AA146: =(M146-M145)*1000 -> 7087 | AB146: =M146/M145-1 -> 0.0020439099 | AC146: =(M146-$M$146)*1000 -> 0 | AD146: =M146/$M$146-1 -> 0 | AF146: =(N146-N145)*1000 -> -2269 | AG146: =N146/N145-1 -> -0.0048871476 | AH146: =(N146-$N$177)*1000 -> -38233 | AI146: =N146/$N$177-1 -> -0.076428856
A147: 45292 | B147: 6326.652 | C147: 3443.415 | D147: 459.719 | E147: 384.522 | F147: 2064.337 | G147: 648.302 | H147: =+SUM(B147:G147) -> 13326.947 | J147: =A147 -> 45292 | K147: =B147+C147+D147 -> 10229.786 | L147: =B147 -> 6326.652 | M147: =C147 -> 3443.415 | N147: =D147 -> 459.719 | O147: =E147+F147+G147 -> 3097.161 | Q147: =(K147-K146)*1000 -> -68003 | R147: =K147/K146-1 -> -0.0066036506 | S147: =(K147-$K$142)*1000 -> -113959 | T147: =K147/$K$142-1 -> -0.01101719 | V147: =(L147-L146)*1000 -> -34666 | W147: =L147/L146-1 -> -0.0054494996 | X147: =(L147-$L$142)*1000 -> -81484 | Y147: =L147/$L$142-1 -> -0.01271571 | AA147: =(M147-M146)*1000 -> -31046 | AB147: =M147/M146-1 -> -0.0089354867 | AC147: =(M147-$M$146)*1000 -> -31046 | AD147: =M147/$M$146-1 -> -0.0089354867 | AF147: =(N147-N146)*1000 -> -2291 | AG147: =N147/N146-1 -> -0.0049587671 | AH147: =(N147-$N$177)*1000 -> -40524 | AI147: =N147/$N$177-1 -> -0.08100863
A148: 45323 | B148: 6300.738 | C148: 3443.51 | D148: 457.521 | E148: 407.191 | F148: 2079.465 | G148: 643.78 | H148: =+SUM(B148:G148) -> 13332.205 | J148: =A148 -> 45323 | K148: =B148+C148+D148 -> 10201.769 | L148: =B148 -> 6300.738 | M148: =C148 -> 3443.51 | N148: =D148 -> 457.521 | O148: =E148+F148+G148 -> 3130.436 | Q148: =(K148-K147)*1000 -> -28017 | R148: =K148/K147-1 -> -0.002738767 | S148: =(K148-$K$142)*1000 -> -141976 | T148: =K148/$K$142-1 -> -0.013725783 | V148: =(L148-L147)*1000 -> -25914 | W148: =L148/L147-1 -> -0.0040960053 | X148: =(L148-$L$142)*1000 -> -107398 | Y148: =L148/$L$142-1 -> -0.016759632 | AA148: =(M148-M147)*1000 -> 95 | AB148: =M148/M147-1 -> 2.7588891e-05 | AC148: =(M148-$M$146)*1000 -> -30951 | AD148: =M148/$M$146-1 -> -0.0089081443 | AF148: =(N148-N147)*1000 -> -2198 | AG148: =N148/N147-1 -> -0.0047811815 | AH148: =(N148-$N$177)*1000 -> -42722 | AI148: =N148/$N$177-1 -> -0.085402494
A149: 45352 | B149: 6275.855 | C149: 3440.809 | D149: 455.624 | E149: 409.833 | F149: 2077.508 | G149: 631.509 | H149: =+SUM(B149:G149) -> 13291.138 | J149: =A149 -> 45352 | K149: =B149+C149+D149 -> 10172.288 | L149: =B149 -> 6275.855 | M149: =C149 -> 3440.809 | N149: =D149 -> 455.624 | O149: =E149+F149+G149 -> 3118.85 | Q149: =(K149-K148)*1000 -> -29481 | R149: =K149/K148-1 -> -0.0028897929 | S149: =(K149-$K$142)*1000 -> -171457 | T149: =K149/$K$142-1 -> -0.016575911 | V149: =(L149-L148)*1000 -> -24883 | W149: =L149/L148-1 -> -0.0039492199 | X149: =(L149-$L$142)*1000 -> -132281 | Y149: =L149/$L$142-1 -> -0.020642664 | AA149: =(M149-M148)*1000 -> -2701 | AB149: =M149/M148-1 -> -0.00078437408 | AC149: =(M149-$M$146)*1000 -> -33652 | AD149: =M149/$M$146-1 -> -0.0096855311 | AF149: =(N149-N148)*1000 -> -1897 | AG149: =N149/N148-1 -> -0.0041462578 | AH149: =(N149-$N$177)*1000 -> -44619 | AI149: =N149/$N$177-1 -> -0.089194651
A150: 45383 | B150: 6258.796 | C150: 3437.569 | D150: 453.288 | E150: 410.935 | F150: 2077.369 | G150: 631.509 | H150: =+SUM(B150:G150) -> 13269.466 | J150: =A150 -> 45383 | K150: =B150+C150+D150 -> 10149.653 | L150: =B150 -> 6258.796 | M150: =C150 -> 3437.569 | N150: =D150 -> 453.288 | O150: =E150+F150+G150 -> 3119.813 | Q150: =(K150-K149)*1000 -> -22635 | R150: =K150/K149-1 -> -0.0022251631 | S150: =(K150-$K$142)*1000 -> -194092 | T150: =K150/$K$142-1 -> -0.01876419 | V150: =(L150-L149)*1000 -> -17059 | W150: =L150/L149-1 -> -0.0027181954 | X150: =(L150-$L$142)*1000 -> -149340 | Y150: =L150/$L$142-1 -> -0.023304749 | AA150: =(M150-M149)*1000 -> -3240 | AB150: =M150/M149-1 -> -0.00094163902 | AC150: =(M150-$M$146)*1000 -> -36892 | AD150: =M150/$M$146-1 -> -0.01061805 | AF150: =(N150-N149)*1000 -> -2336 | AG150: =N150/N149-1 -> -0.0051270346 | AH150: =(N150-$N$177)*1000 -> -46955 | AI150: =N150/$N$177-1 -> -0.093864382
A151: 45413 | B151: 6248.969 | C151: 3430.921 | D151: 451.328 | E151: 409.351 | F151: 2072.457 | G151: 651.195 | H151: =+SUM(B151:G151) -> 13264.221 | J151: =A151 -> 45413 | K151: =B151+C151+D151 -> 10131.218 | L151: =B151 -> 6248.969 | M151: =C151 -> 3430.921 | N151: =D151 -> 451.328 | O151: =E151+F151+G151 -> 3133.003 | Q151: =(K151-K150)*1000 -> -18435 | R151: =K151/K150-1 -> -0.0018163183 | S151: =(K151-$K$142)*1000 -> -212527 | T151: =K151/$K$142-1 -> -0.020546427 | V151: =(L151-L150)*1000 -> -9827 | W151: =L151/L150-1 -> -0.0015701103 | X151: =(L151-$L$142)*1000 -> -159167 | Y151: =L151/$L$142-1 -> -0.024838268 | AA151: =(M151-M150)*1000 -> -6648 | AB151: =M151/M150-1 -> -0.0019339248 | AC151: =(M151-$M$146)*1000 -> -43540 | AD151: =M151/$M$146-1 -> -0.01253144 | AF151: =(N151-N150)*1000 -> -1960 | AG151: =N151/N150-1 -> -0.0043239618 | AH151: =(N151-$N$177)*1000 -> -48915 | AI151: =N151/$N$177-1 -> -0.097782478
A152: 45444 | B152: 6239.26 | C152: 3425.69 | D152: 450.72 | E152: 408.841 | F152: 2069.413 | G152: 657.714 | H152: =+SUM(B152:G152) -> 13251.638 | J152: =A152 -> 45444 | K152: =B152+C152+D152 -> 10115.67 | L152: =B152 -> 6239.26 | M152: =C152 -> 3425.69 | N152: =D152 -> 450.72 | O152: =E152+F152+G152 -> 3135.968 | Q152: =(K152-K151)*1000 -> -15548 | R152: =K152/K151-1 -> -0.0015346625 | S152: =(K152-$K$142)*1000 -> -228075 | T152: =K152/$K$142-1 -> -0.022049557 | V152: =(L152-L151)*1000 -> -9709 | W152: =L152/L151-1 -> -0.0015536963 | X152: =(L152-$L$142)*1000 -> -168876 | Y152: =L152/$L$142-1 -> -0.026353373 | AA152: =(M152-M151)*1000 -> -5231 | AB152: =M152/M151-1 -> -0.0015246635 | AC152: =(M152-$M$146)*1000 -> -48771 | AD152: =M152/$M$146-1 -> -0.014036997 | AF152: =(N152-N151)*1000 -> -608 | AG152: =N152/N151-1 -> -0.0013471356 | AH152: =(N152-$N$177)*1000 -> -49523 | AI152: =N152/$N$177-1 -> -0.098997887
A153: 45474 | B153: 6233.118 | C153: 3422.31 | D153: 449.481 | E153: 407.485 | F153: 2088.884 | G153: 647.813 | H153: =+SUM(B153:G153) -> 13249.091 | J153: =A153 -> 45474 | K153: =B153+C153+D153 -> 10104.909 | L153: =B153 -> 6233.118 | M153: =C153 -> 3422.31 | N153: =D153 -> 449.481 | O153: =E153+F153+G153 -> 3144.182 | Q153: =(K153-K152)*1000 -> -10761 | R153: =K153/K152-1 -> -0.0010637951 | S153: =(K153-$K$142)*1000 -> -238836 | T153: =K153/$K$142-1 -> -0.023089896 | V153: =(L153-L152)*1000 -> -6142 | W153: =L153/L152-1 -> -0.00098441161 | X153: =(L153-$L$142)*1000 -> -175018 | Y153: =L153/$L$142-1 -> -0.027311842 | AA153: =(M153-M152)*1000 -> -3380 | AB153: =M153/M152-1 -> -0.00098666254 | AC153: =(M153-$M$146)*1000 -> -52151 | AD153: =M153/$M$146-1 -> -0.01500981 | AF153: =(N153-N152)*1000 -> -1239 | AG153: =N153/N152-1 -> -0.002748935 | AH153: =(N153-$N$177)*1000 -> -50762 | AI153: =N153/$N$177-1 -> -0.10147468
A154: 45505 | B154: 6237.229 | C154: 3419.735 | D154: 449.339 | E154: 405.623 | F154: 2111.035 | G154: 649.309 | H154: =+SUM(B154:G154) -> 13272.27 | J154: =A154 -> 45505 | K154: =B154+C154+D154 -> 10106.303 | L154: =B154 -> 6237.229 | M154: =C154 -> 3419.735 | N154: =D154 -> 449.339 | O154: =E154+F154+G154 -> 3165.967 | Q154: =(K154-K153)*1000 -> 1394 | R154: =K154/K153-1 -> 0.00013795275 | S154: =(K154-$K$142)*1000 -> -237442 | T154: =K154/$K$142-1 -> -0.022955129 | V154: =(L154-L153)*1000 -> 4111 | W154: =L154/L153-1 -> 0.0006595415 | X154: =(L154-$L$142)*1000 -> -170907 | Y154: =L154/$L$142-1 -> -0.026670314 | AA154: =(M154-M153)*1000 -> -2575 | AB154: =M154/M153-1 -> -0.00075241577 | AC154: =(M154-$M$146)*1000 -> -54726 | AD154: =M154/$M$146-1 -> -0.015750932 | AF154: =(N154-N153)*1000 -> -142 | AG154: =N154/N153-1 -> -0.00031591992 | AH154: =(N154-$N$177)*1000 -> -50904 | AI154: =N154/$N$177-1 -> -0.10175855
A155: 45536 | B155: 6246.337 | C155: 3418.793 | D155: 449.33 | E155: 404.302 | F155: 2110.734 | G155: 651.068 | H155: =+SUM(B155:G155) -> 13280.564 | J155: =A155 -> 45536 | K155: =B155+C155+D155 -> 10114.46 | L155: =B155 -> 6246.337 | M155: =C155 -> 3418.793 | N155: =D155 -> 449.33 | O155: =E155+F155+G155 -> 3166.104 | Q155: =(K155-K154)*1000 -> 8157 | R155: =K155/K154-1 -> 0.00080712007 | S155: =(K155-$K$142)*1000 -> -229285 | T155: =K155/$K$142-1 -> -0.022166536 | V155: =(L155-L154)*1000 -> 9108 | W155: =L155/L154-1 -> 0.0014602638 | X155: =(L155-$L$142)*1000 -> -161799 | Y155: =L155/$L$142-1 -> -0.025248996 | AA155: =(M155-M154)*1000 -> -942 | AB155: =M155/M154-1 -> -0.00027545994 | AC155: =(M155-$M$146)*1000 -> -55668 | AD155: =M155/$M$146-1 -> -0.016022053 | AF155: =(N155-N154)*1000 -> -9 | AG155: =N155/N154-1 -> -2.0029421e-05 | AH155: =(N155-$N$177)*1000 -> -50913 | AI155: =N155/$N$177-1 -> -0.10177654
A156: 45566 | B156: 6253.879 | C156: 3420.425 | D156: 448.41 | E156: 402.315 | F156: 2097.846 | G156: 650.96 | H156: =+SUM(B156:G156) -> 13273.835 | J156: =A156 -> 45566 | K156: =B156+C156+D156 -> 10122.714 | L156: =B156 -> 6253.879 | M156: =C156 -> 3420.425 | N156: =D156 -> 448.41 | O156: =E156+F156+G156 -> 3151.121 | Q156: =(K156-K155)*1000 -> 8254 | R156: =K156/K155-1 -> 0.00081605938 | S156: =(K156-$K$142)*1000 -> -221031 | T156: =K156/$K$142-1 -> -0.021368566 | V156: =(L156-L155)*1000 -> 7542 | W156: =L156/L155-1 -> 0.0012074276 | X156: =(L156-$L$142)*1000 -> -154257 | Y156: =L156/$L$142-1 -> -0.024072055 | AA156: =(M156-M155)*1000 -> 1632 | AB156: =M156/M155-1 -> 0.00047736145 | AC156: =(M156-$M$146)*1000 -> -54036 | AD156: =M156/$M$146-1 -> -0.01555234 | AF156: =(N156-N155)*1000 -> -920 | AG156: =N156/N155-1 -> -0.0020474929 | AH156: =(N156-$N$177)*1000 -> -51833 | AI156: =N156/$N$177-1 -> -0.10361564
A157: 45597 | B157: 6255.158 | C157: 3417.805 | D157: 447.669 | E157: 400.831 | F157: 2086.574 | G157: 653.385 | H157: =+SUM(B157:G157) -> 13261.422 | J157: =A157 -> 45597 | K157: =B157+C157+D157 -> 10120.632 | L157: =B157 -> 6255.158 | M157: =C157 -> 3417.805 | N157: =D157 -> 447.669 | O157: =E157+F157+G157 -> 3140.79 | Q157: =(K157-K156)*1000 -> -2082 | R157: =K157/K156-1 -> -0.00020567607 | S157: =(K157-$K$142)*1000 -> -223113 | T157: =K157/$K$142-1 -> -0.021569847 | V157: =(L157-L156)*1000 -> 1279 | W157: =L157/L156-1 -> 0.00020451307 | X157: =(L157-$L$142)*1000 -> -152978 | Y157: =L157/$L$142-1 -> -0.023872465 | AA157: =(M157-M156)*1000 -> -2620 | AB157: =M157/M156-1 -> -0.00076598668 | AC157: =(M157-$M$146)*1000 -> -56656 | AD157: =M157/$M$146-1 -> -0.016306414 | AF157: =(N157-N156)*1000 -> -741 | AG157: =N157/N156-1 -> -0.0016525055 | AH157: =(N157-$N$177)*1000 -> -52574 | AI157: =N157/$N$177-1 -> -0.10509692
... A175: 46143 | B175: 6131.521 | C175: 3387.509 | D175: 447.955 | E175: 388.208 | F175: 2198.335 | G175: 232.076 | H175: =+SUM(B175:G175) -> 12785.604 | J175: =A175 -> 46143 | K175: =B175+C175+D175 -> 9966.985 | L175: =B175 -> 6131.521 | M175: =C175 -> 3387.509 | N175: =D175 -> 447.955 | O175: =E175+F175+G175 -> 2818.619 | Q175: =(K175-K174)*1000 -> -6971 | R175: =K175/K174-1 -> -0.00069892027 | S175: =(K175-$K$142)*1000 -> -376760 | T175: =K175/$K$142-1 -> -0.036423945 | V175: =(L175-L174)*1000 -> -9059 | W175: =L175/L174-1 -> -0.0014752678 | X175: =(L175-$L$142)*1000 -> -276615 | Y175: =L175/$L$142-1 -> -0.043166219 | AA175: =(M175-M174)*1000 -> 736 | AB175: =M175/M174-1 -> 0.00021731601 | AC175: =(M175-$M$146)*1000 -> -86952 | AD175: =M175/$M$146-1 -> -0.02502604 | AF175: =(N175-N174)*1000 -> 1352 | AG175: =N175/N174-1 -> 0.0030272972 | AH175: =(N175-$N$177)*1000 -> -52288 | AI175: =N175/$N$177-1 -> -0.1045252
S176: =(K176-$K$142)*1000 -> -10343745 | T176: =K176/$K$142-1 -> -1
J177: MAX | K177: =MAX(K3:K176) -> 10343.745 | L177: =MAX(L3:L174) -> 6408.136 | M177: =MAX(M3:M174) -> 3474.461 | N177: =MAX(N3:N174) -> 500.243 | O177: =MAX(O3:O174) -> 3166.104
K178: =HLOOKUP(K$2,$J$2:$O$1723,MATCH(MAX($J$2:$J$1723),$J$2:$J$1723,0),FALSE)-K177 -> -376.76 | L178: =HLOOKUP(L$2,$J$2:$O$1723,MATCH(MAX($J$2:$J$1723),$J$2:$J$1723,0),FALSE)-L177 -> -276.615 | M178: =HLOOKUP(M$2,$J$2:$O$1723,MATCH(MAX($J$2:$J$1723),$J$2:$J$1723,0),FALSE)-M177 -> -86.952 | N178: =HLOOKUP(N$2,$J$2:$O$1723,MATCH(MAX($J$2:$J$1723),$J$2:$J$1723,0),FALSE)-N177 -> -52.288 | O178: =HLOOKUP(O$2,$J$2:$O$1723,MATCH(MAX($J$2:$J$1723),$J$2:$J$1723,0),FALSE)-O177 -> -347.485
K179: =HLOOKUP(K$2,$J$2:$O$1723,MATCH(MAX($J$2:$J$1723),$J$2:$J$1723,0),FALSE)/K177-1 -> -0.036423945 | L179: =HLOOKUP(L$2,$J$2:$O$1723,MATCH(MAX($J$2:$J$1723),$J$2:$J$1723,0),FALSE)/L177-1 -> -0.043166219 | M179: =HLOOKUP(M$2,$J$2:$O$1723,MATCH(MAX($J$2:$J$1723),$J$2:$J$1723,0),FALSE)/M177-1 -> -0.02502604 | N179: =HLOOKUP(N$2,$J$2:$O$1723,MATCH(MAX($J$2:$J$1723),$J$2:$J$1723,0),FALSE)/N177-1 -> -0.1045252 | O179: =HLOOKUP(O$2,$J$2:$O$1723,MATCH(MAX($J$2:$J$1723),$J$2:$J$1723,0),FALSE)/O177-1 -> -0.10975161
J180: VAR ABS. | K180: =(HLOOKUP(K$2,$J$2:$O$1723,MATCH(MAX($J$2:$J$1723),$J$2:$J$1723,0),FALSE)-HLOOKUP(K$2,$J$2:$O$1723,MATCH(MAX($J$2:$J$1723),$J$2:$J$1723,0)-1,FALSE))*1000 -> -6971 | L180: =(HLOOKUP(L$2,$J$2:$O$1723,MATCH(MAX($J$2:$J$1723),$J$2:$J$1723,0),FALSE)-HLOOKUP(L$2,$J$2:$O$1723,MATCH(MAX($J$2:$J$1723),$J$2:$J$1723,0)-1,FALSE))*1000 -> -9059 | M180: =(HLOOKUP(M$2,$J$2:$O$1723,MATCH(MAX($J$2:$J$1723),$J$2:$J$1723,0),FALSE)-HLOOKUP(M$2,$J$2:$O$1723,MATCH(MAX($J$2:$J$1723),$J$2:$J$1723,0)-1,FALSE))*1000 -> 736 | N180: =(HLOOKUP(N$2,$J$2:$O$1723,MATCH(MAX($J$2:$J$1723),$J$2:$J$1723,0),FALSE)-HLOOKUP(N$2,$J$2:$O$1723,MATCH(MAX($J$2:$J$1723),$J$2:$J$1723,0)-1,FALSE))*1000 -> 1352 | O180: =(HLOOKUP(O$2,$J$2:$O$1723,MATCH(MAX($J$2:$J$1723),$J$2:$J$1723,0),FALSE)-HLOOKUP(O$2,$J$2:$O$1723,MATCH(MAX($J$2:$J$1723),$J$2:$J$1723,0)-1,FALSE))*1000 -> -5009 | Q180: =(K169-K168)*1000 -> -21239 | R180: =K169/K168-1 -> -0.0021152276 | S180: =(K169-$K$142)*1000 -> -323984 | T180: =K169/$K$142-1 -> -0.031321731 | V180: =(L169-L168)*1000 -> -16459 | W180: =L169/L168-1 -> -0.0026542814 | X180: =(L169-$L$142)*1000 -> -223670 | Y180: =L169/$L$142-1 -> -0.034904066 | AA180: =(M169-M168)*1000 -> -6006 | AB180: =M169/M168-1 -> -0.0017652655 | AC180: =(M169-$M$146)*1000 -> -78146 | AD180: =M169/$M$146-1 -> -0.022491546 | AF180: =(N169-N168)*1000 -> 1226 | AG180: =N169/N168-1 -> 0.0028006597 | AH180: =(N169-$N$177)*1000 -> -61263 | AI180: =N169/$N$177-1 -> -0.12246648
J181: CONTRIB. | K181: =K180/$K$180 -> 1 | L181: =L180/$K$180 -> 1.2995266 | M181: =M180/$K$180 -> -0.10558026 | N181: =N180/$K$180 -> -0.19394635 | O181: =O180/$K$180 -> 0.71854827
J182: VAR REL. | K182: =(HLOOKUP(K$2,$J$2:$O$1723,MATCH(MAX($J$2:$J$1723),$J$2:$J$1723,0),FALSE)/HLOOKUP(K$2,$J$2:$O$1723,MATCH(MAX($J$2:$J$1723),$J$2:$J$1723,0)-1,FALSE))-1 -> -0.00069892027 | L182: =(HLOOKUP(L$2,$J$2:$O$1723,MATCH(MAX($J$2:$J$1723),$J$2:$J$1723,0),FALSE)/HLOOKUP(L$2,$J$2:$O$1723,MATCH(MAX($J$2:$J$1723),$J$2:$J$1723,0)-1,FALSE))-1 -> -0.0014752678 | M182: =(HLOOKUP(M$2,$J$2:$O$1723,MATCH(MAX($J$2:$J$1723),$J$2:$J$1723,0),FALSE)/HLOOKUP(M$2,$J$2:$O$1723,MATCH(MAX($J$2:$J$1723),$J$2:$J$1723,0)-1,FALSE))-1 -> 0.00021731601 | N182: =(HLOOKUP(N$2,$J$2:$O$1723,MATCH(MAX($J$2:$J$1723),$J$2:$J$1723,0),FALSE)/HLOOKUP(N$2,$J$2:$O$1723,MATCH(MAX($J$2:$J$1723),$J$2:$J$1723,0)-1,FALSE))-1 -> 0.0030272972 | O182: =(HLOOKUP(O$2,$J$2:$O$1723,MATCH(MAX($J$2:$J$1723),$J$2:$J$1723,0),FALSE)/HLOOKUP(O$2,$J$2:$O$1723,MATCH(MAX($J$2:$J$1723),$J$2:$J$1723,0)-1,FALSE))-1 -> -0.0017739589
...

Sheet A.2.2
A1: Personas con empleo asalariado registrado del sector privado, según rama de actividad. Sin estacionalidad
T2: Total privados | W2: Industria | AA2: Construcción | AE2: Comercio
A3: Período | B3: Agricultura, ganaderÍa, caza y silvicultura | C3: Pesca | D3: Explotación de minas y canteras | E3: Industrias manufactureras | F3: Suministro de electricidad, gas y agua | G3: Construcción | H3: Comercio y reparaciones | I3: Hoteles y restaurantes | J3: Transporte, almacenamiento y comunicación | K3: Intermediación financiera | L3: Actividades inmobiliarias, empresariales y de alquiler | M3: Enseñanza | N3: Servicios sociales y de salud | O3: Servicios comunitarios, sociales y personales | P3: Sin especificar | Q3: Total | T3: Var. Mensual % | U3: Var. Mensual absoluta | W3: Var. Mensual % | X3: Var. Mensual absoluta | Y3: Índice, Oct-2013=100 | AA3: Var. Mensual % | AB3: Var. Mensual absoluta | AC3: Índice, Mayo-2023=100 | AE3: Var. Mensual % | AF3: Var. Mensual absoluta | AG3: Índice, Marzo-2025=100
A4: 39814 | B4: 332.633 | C4: 15.223 | D4: 68.535 | E4: 1182.979 | F4: 54.39 | G4: 403.933 | H4: 1003.797 | I4: 218.286 | J4: 487.742 | K4: 144.589 | L4: 814.716 | M4: 322.844 | N4: 232.437 | O4: 340.573 | P4: 1.501 | Q4: 5624.178 | S4: =A4 -> 39814 | Y4: =E4/$E$61*100 -> 93.445802 | AC4: =G4/$G$176*100 -> 85.753075 | AG4: =H4/$H$200*100 -> 79.745795
A5: 39845 | B5: 329.735 | C5: 15.106 | D5: 68.213 | E5: 1178.469 | F5: 54.459 | G5: 402.106 | H5: 1006.087 | I5: 219.111 | J5: 486.784 | K5: 141.626 | L5: 810.209 | M5: 321.777 | N5: 233.859 | O5: 339.719 | P5: 1.511 | Q5: 5608.771 | S5: =A5 -> 39845 | T5: =Q5/Q4-1 -> -0.0027394225 | U5: =(Q5-Q4)*1000 -> -15407 | W5: =E5/E4-1 -> -0.0038124092 | X5: =(E5-E4)*1000 -> -4510 | Y5: =E5/$E$61*100 -> 93.089548 | AA5: =G5/G4-1 -> -0.0045230273 | AB5: =(G5-G4)*1000 -> -1827 | AC5: =G5/$G$176*100 -> 85.365212 | AE5: =H5/H4-1 -> 0.0022813378 | AF5: =(H5-H4)*1000 -> 2290 | AG5: =H5/$H$200*100 -> 79.927722
A6: 39873 | B6: 328.879 | C6: 15.234 | D6: 67.266 | E6: 1169.22 | F6: 54.46 | G6: 398.956 | H6: 1006.015 | I6: 219.567 | J6: 486.255 | K6: 140.838 | L6: 807.779 | M6: 321.868 | N6: 234.424 | O6: 339.802 | P6: 1.413 | Q6: 5591.976 | S6: =A6 -> 39873 | T6: =Q6/Q5-1 -> -0.0029944171 | U6: =(Q6-Q5)*1000 -> -16795 | W6: =E6/E5-1 -> -0.0078483185 | X6: =(E6-E5)*1000 -> -9249 | Y6: =E6/$E$61*100 -> 92.358952 | AA6: =G6/G5-1 -> -0.0078337553 | AB6: =(G6-G5)*1000 -> -3150 | AC6: =G6/$G$176*100 -> 84.696481 | AE6: =H6/H5-1 -> -7.1564388e-05 | AF6: =(H6-H5)*1000 -> -72 | AG6: =H6/$H$200*100 -> 79.922002
A7: 39904 | B7: 326.886 | C7: 15.268 | D7: 66.935 | E7: 1160.638 | F7: 54.61 | G7: 396.808 | H7: 1005.835 | I7: 220.046 | J7: 486.036 | K7: 140.011 | L7: 802.129 | M7: 322.341 | N7: 235.324 | O7: 339.741 | P7: 1.345 | Q7: 5573.953 | S7: =A7 -> 39904 | T7: =Q7/Q6-1 -> -0.003223011 | U7: =(Q7-Q6)*1000 -> -18023 | W7: =E7/E6-1 -> -0.007339936 | X7: =(E7-E6)*1000 -> -8582 | Y7: =E7/$E$61*100 -> 91.681043 | AA7: =G7/G6-1 -> -0.0053840524 | AB7: =(G7-G6)*1000 -> -2148 | AC7: =G7/$G$176*100 -> 84.240471 | AE7: =H7/H6-1 -> -0.00017892377 | AF7: =(H7-H6)*1000 -> -180 | AG7: =H7/$H$200*100 -> 79.907702
A8: 39934 | B8: 325.081 | C8: 15.377 | D8: 66.975 | E8: 1157.451 | F8: 54.702 | G8: 395.525 | H8: 1005.454 | I8: 219.962 | J8: 485.655 | K8: 139.629 | L8: 801.651 | M8: 322.776 | N8: 236.098 | O8: 340.232 | P8: 1.332 | Q8: 5567.9 | S8: =A8 -> 39934 | T8: =Q8/Q7-1 -> -0.0010859439 | U8: =(Q8-Q7)*1000 -> -6053 | W8: =E8/E7-1 -> -0.0027459035 | X8: =(E8-E7)*1000 -> -3187 | Y8: =E8/$E$61*100 -> 91.429296 | AA8: =G8/G7-1 -> -0.0032333017 | AB8: =(G8-G7)*1000 -> -1283 | AC8: =G8/$G$176*100 -> 83.968096 | AE8: =H8/H7-1 -> -0.00037878976 | AF8: =(H8-H7)*1000 -> -381 | AG8: =H8/$H$200*100 -> 79.877434
A9: 39965 | B9: 326.386 | C9: 15 | D9: 66.949 | E9: 1160.323 | F9: 55.469 | G9: 395.792 | H9: 1006.542 | I9: 220.305 | J9: 485.158 | K9: 139.607 | L9: 801.952 | M9: 324.13 | N9: 237.048 | O9: 340.208 | P9: 1.303 | Q9: 5576.172 | S9: =A9 -> 39965 | T9: =Q9/Q8-1 -> 0.0014856589 | U9: =(Q9-Q8)*1000 -> 8272 | W9: =E9/E8-1 -> 0.0024813145 | X9: =(E9-E8)*1000 -> 2872 | Y9: =E9/$E$61*100 -> 91.656161 | AA9: =G9/G8-1 -> 0.00067505215 | AB9: =(G9-G8)*1000 -> 267 | AC9: =G9/$G$176*100 -> 84.024779 | AE9: =H9/H8-1 -> 0.0010820982 | AF9: =(H9-H8)*1000 -> 1088 | AG9: =H9/$H$200*100 -> 79.963869
A10: 39995 | B10: 327.447 | C10: 14.687 | D10: 66.822 | E10: 1159.728 | F10: 55.51 | G10: 393.752 | H10: 1006.314 | I10: 217.325 | J10: 484.742 | K10: 139.431 | L10: 815.844 | M10: 323.038 | N10: 238.131 | O10: 338.974 | P10: 1.284 | Q10: 5583.029 | S10: =A10 -> 39995 | T10: =Q10/Q9-1 -> 0.0012296966 | U10: =(Q10-Q9)*1000 -> 6857 | W10: =E10/E9-1 -> -0.00051278825 | X10: =(E10-E9)*1000 -> -595 | Y10: =E10/$E$61*100 -> 91.609161 | AA10: =G10/G9-1 -> -0.0051542224 | AB10: =(G10-G9)*1000 -> -2040 | AC10: =G10/$G$176*100 -> 83.591697 | AE10: =H10/H9-1 -> -0.00022651812 | AF10: =(H10-H9)*1000 -> -228 | AG10: =H10/$H$200*100 -> 79.945756
A11: 40026 | B11: 328.554 | C11: 14.652 | D11: 66.68 | E11: 1161.436 | F11: 55.656 | G11: 392.654 | H11: 1007.968 | I11: 218.075 | J11: 484.97 | K11: 139.499 | L11: 797.716 | M11: 324.899 | N11: 238.644 | O11: 340.035 | P11: 1.265 | Q11: 5572.703 | S11: =A11 -> 40026 | T11: =Q11/Q10-1 -> -0.0018495336 | U11: =(Q11-Q10)*1000 -> -10326 | W11: =E11/E10-1 -> 0.0014727591 | X11: =(E11-E10)*1000 -> 1708 | Y11: =E11/$E$61*100 -> 91.744079 | AA11: =G11/G10-1 -> -0.0027885573 | AB11: =(G11-G10)*1000 -> -1098 | AC11: =G11/$G$176*100 -> 83.358596 | AE11: =H11/H10-1 -> 0.0016436222 | AF11: =(H11-H10)*1000 -> 1654 | AG11: =H11/$H$200*100 -> 80.077156
A12: 40057 | B12: 327.357 | C12: 14.775 | D12: 66.606 | E12: 1163.915 | F12: 55.822 | G12: 389.827 | H12: 1010.074 | I12: 219.967 | J12: 484.327 | K12: 139.412 | L12: 802.806 | M12: 326.434 | N12: 239.323 | O12: 343.2 | P12: 1.216 | Q12: 5585.061 | S12: =A12 -> 40057 | T12: =Q12/Q11-1 -> 0.0022175953 | U12: =(Q12-Q11)*1000 -> 12358 | W12: =E12/E11-1 -> 0.0021344267 | X12: =(E12-E11)*1000 -> 2479 | Y12: =E12/$E$61*100 -> 91.9399 | AA12: =G12/G11-1 -> -0.0071997229 | AB12: =(G12-G11)*1000 -> -2827 | AC12: =G12/$G$176*100 -> 82.758438 | AE12: =H12/H11-1 -> 0.002089352 | AF12: =(H12-H11)*1000 -> 2106 | AG12: =H12/$H$200*100 -> 80.244466
A13: 40087 | B13: 328.352 | C13: 14.586 | D13: 66.649 | E13: 1167.484 | F13: 55.965 | G13: 388.271 | H13: 1011.654 | I13: 221.779 | J13: 485.844 | K13: 139.544 | L13: 805.269 | M13: 327.221 | N13: 239.795 | O13: 345.676 | P13: 1.181 | Q13: 5599.27 | S13: =A13 -> 40087 | T13: =Q13/Q12-1 -> 0.0025441083 | U13: =(Q13-Q12)*1000 -> 14209 | W13: =E13/E12-1 -> 0.0030663751 | X13: =(E13-E12)*1000 -> 3569 | Y13: =E13/$E$61*100 -> 92.221822 | AA13: =G13/G12-1 -> -0.0039915142 | AB13: =(G13-G12)*1000 -> -1556 | AC13: =G13/$G$176*100 -> 82.428106 | AE13: =H13/H12-1 -> 0.0015642418 | AF13: =(H13-H12)*1000 -> 1580 | AG13: =H13/$H$200*100 -> 80.369987
A14: 40118 | B14: 328.769 | C14: 14.642 | D14: 66.567 | E14: 1166.998 | F14: 56.06 | G14: 387.357 | H14: 1014.826 | I14: 221.712 | J14: 486.423 | K14: 139.928 | L14: 803.713 | M14: 328.225 | N14: 240.533 | O14: 345.609 | P14: 1.187 | Q14: 5602.549 | S14: =A14 -> 40118 | T14: =Q14/Q13-1 -> 0.00058561205 | U14: =(Q14-Q13)*1000 -> 3279 | W14: =E14/E13-1 -> -0.00041627979 | X14: =(E14-E13)*1000 -> -486 | Y14: =E14/$E$61*100 -> 92.183432 | AA14: =G14/G13-1 -> -0.0023540259 | AB14: =(G14-G13)*1000 -> -914 | AC14: =G14/$G$176*100 -> 82.234068 | AE14: =H14/H13-1 -> 0.0031354594 | AF14: =(H14-H13)*1000 -> 3172 | AG14: =H14/$H$200*100 -> 80.621984
A15: 40148 | B15: 324.799 | C15: 14.705 | D15: 66.722 | E15: 1167.177 | F15: 56.111 | G15: 387.337 | H15: 1014.107 | I15: 222.778 | J15: 487.276 | K15: 140.25 | L15: 809.516 | M15: 328.927 | N15: 241.24 | O15: 347.013 | P15: 1.195 | Q15: 5609.153 | S15: =A15 -> 40148 | T15: =Q15/Q14-1 -> 0.0011787492 | U15: =(Q15-Q14)*1000 -> 6604 | W15: =E15/E14-1 -> 0.00015338501 | X15: =(E15-E14)*1000 -> 179 | Y15: =E15/$E$61*100 -> 92.197571 | AA15: =G15/G14-1 -> -5.1631957e-05 | AB15: =(G15-G14)*1000 -> -20 | AC15: =G15/$G$176*100 -> 82.229822 | AE15: =H15/H14-1 -> -0.00070849584 | AF15: =(H15-H14)*1000 -> -719 | AG15: =H15/$H$200*100 -> 80.564864
A16: 40179 | B16: 323.057 | C16: 14.607 | D16: 66.783 | E16: 1168.457 | F16: 56.173 | G16: 388.259 | H16: 1015.381 | I16: 222.668 | J16: 487.886 | K16: 140.495 | L16: 810.922 | M16: 329.147 | N16: 242.333 | O16: 346.074 | P16: 1.181 | Q16: 5613.423 | S16: =A16 -> 40179 | T16: =Q16/Q15-1 -> 0.00076125575 | U16: =(Q16-Q15)*1000 -> 4270 | W16: =E16/E15-1 -> 0.0010966631 | X16: =(E16-E15)*1000 -> 1280 | Y16: =E16/$E$61*100 -> 92.298681 | AA16: =G16/G15-1 -> 0.0023803561 | AB16: =(G16-G15)*1000 -> 922 | AC16: =G16/$G$176*100 -> 82.425559 | AE16: =H16/H15-1 -> 0.0012562777 | AF16: =(H16-H15)*1000 -> 1274 | AG16: =H16/$H$200*100 -> 80.666076
... A212: 46143 | B212: 322.635 | C212: 13.977 | D212: 86.692 | E212: 1108.347 | F212: 76.358 | G212: 378.194 | H212: 1219.592 | I212: 276.838 | J212: 503.726 | K212: 143.49 | L212: 878.772 | M212: 423.79 | N212: 330.063 | O212: 368.889 | P212: 0.158 | Q212: 6131.521 | S212: =A212 -> 46143 | T212: =Q212/Q211-1 -> -0.0014752678 | U212: =(Q212-Q211)*1000 -> -9059 | W212: =E212/E211-1 -> -0.0028402957 | X212: =(E212-E211)*1000 -> -3157 | Y212: =E212/$E$61*100 -> 87.550476 | AA212: =G212/G211-1 -> -0.0052343076 | AB212: =(G212-G211)*1000 -> -1990 | AC212: =G212/$G$176*100 -> 80.288807 | AE212: =H212/H211-1 -> -0.0034433562 | AF212: =(H212-H211)*1000 -> -4214 | AG212: =H212/$H$200*100 -> 96.889444
A214: MAX | B214: =MAX(B4:B212) -> 342.256 | C214: =MAX(C4:C212) -> 15.377 | D214: =MAX(D4:D212) -> 95.893 | E214: =MAX(E4:E212) -> 1265.952 | F214: =MAX(F4:F212) -> 77.176 | G214: =MAX(G4:G212) -> 471.042 | H214: =MAX(H4:H212) -> 1258.746 | I214: =MAX(I4:I212) -> 288.833 | ... Q214: =MAX(Q4:Q212) -> 6408.136
G215: =G214-G208 -> 90.32

Sheet Cuadro 1
B1: Agro y Pesca | C1: Minería | D1: Industria | E1: EGA | F1: Construcción | G1: Comercio | H1: Hoteles y restaurantes | I1: Transporte | J1: Int. Financiera | K1: Serv. Inmobiliarios | L1: Educación | M1: Salud | N1: Serv. Personales | O1: Sin especificar | P1: Total
A2: 45017 | B2: ='A.2.2'!B175+'A.2.2'!C175 -> 324.455 | C2: ='A.2.2'!D175 -> 91.313 | D2: ='A.2.2'!E175 -> 1187.795 | E2: ='A.2.2'!F175 -> 75.877 | F2: ='A.2.2'!G175 -> 470.21 | G2: ='A.2.2'!H175 -> 1207.74 | H2: ='A.2.2'!I175 -> 282.813 | I2: ='A.2.2'!J175 -> 528.421 | J2: ='A.2.2'!K175 -> 152.857 | ... O2: ='A.2.2'!P175 -> 0.186 | P2: =SUM(B2:O2) -> 6351.312 | S2: 45778 | T2: 45809 | U2: 45839 | V2: 45870 | W2: 45901 | X2: 45931 | Y2: 45962 | Z2: 45992 | AA2: 46023 | AB2: 46054 | AC2: 46082 | AD2: 46113 | AE2: 46143
A3: 45047 | B3: ='A.2.2'!B176+'A.2.2'!C176 -> 325.451 | C3: ='A.2.2'!D176 -> 91.963 | D3: ='A.2.2'!E176 -> 1190.376 | E3: ='A.2.2'!F176 -> 75.89 | F3: ='A.2.2'!G176 -> 471.042 | G3: ='A.2.2'!H176 -> 1212.007 | H3: ='A.2.2'!I176 -> 285.101 | I3: ='A.2.2'!J176 -> 529.128 | J3: ='A.2.2'!K176 -> 152.761 | ... O3: ='A.2.2'!P176 -> 0.189 | P3: =SUM(B3:O3) -> 6368.485 | R3: Agro y Pesca | S3: =+HLOOKUP($R3,$A$51:$P$138,MATCH(S$2,$A$51:$A$138,0),FALSE) -> -0.0028534928 | T3: =+HLOOKUP($R3,$A$51:$P$138,MATCH(T$2,$A$51:$A$138,0),FALSE) -> -0.0036070069 | U3: =+HLOOKUP($R3,$A$51:$P$138,MATCH(U$2,$A$51:$A$138,0),FALSE) -> 0.00080212217 | V3: =+HLOOKUP($R3,$A$51:$P$138,MATCH(V$2,$A$51:$A$138,0),FALSE) -> 0.0018040788 | W3: =+HLOOKUP($R3,$A$51:$P$138,MATCH(W$2,$A$51:$A$138,0),FALSE) -> -0.00063523454 | X3: =+HLOOKUP($R3,$A$51:$P$138,MATCH(X$2,$A$51:$A$138,0),FALSE) -> -0.0028423827 | Y3: =+HLOOKUP($R3,$A$51:$P$138,MATCH(Y$2,$A$51:$A$138,0),FALSE) -> 0.0013440577 | Z3: =+HLOOKUP($R3,$A$51:$P$138,MATCH(Z$2,$A$51:$A$138,0),FALSE) -> -0.001183105 | ... AE3: =+HLOOKUP($R3,$A$51:$P$138,MATCH(AE$2,$A$51:$A$138,0),FALSE) -> 0.0054842641
A4: 45078 | B4: ='A.2.2'!B177+'A.2.2'!C177 -> 327.703 | C4: ='A.2.2'!D177 -> 92.558 | D4: ='A.2.2'!E177 -> 1193.029 | E4: ='A.2.2'!F177 -> 75.908 | F4: ='A.2.2'!G177 -> 470.738 | G4: ='A.2.2'!H177 -> 1218.376 | H4: ='A.2.2'!I177 -> 287.722 | I4: ='A.2.2'!J177 -> 530.247 | J4: ='A.2.2'!K177 -> 152.63 | ... O4: ='A.2.2'!P177 -> 0.183 | P4: =SUM(B4:O4) -> 6386.062 | R4: Minería | S4: =+HLOOKUP($R4,$A$51:$P$138,MATCH(S$2,$A$51:$A$138,0),FALSE) -> -0.010194899 | T4: =+HLOOKUP($R4,$A$51:$P$138,MATCH(T$2,$A$51:$A$138,0),FALSE) -> -0.01032208 | U4: =+HLOOKUP($R4,$A$51:$P$138,MATCH(U$2,$A$51:$A$138,0),FALSE) -> -0.0071249328 | V4: =+HLOOKUP($R4,$A$51:$P$138,MATCH(V$2,$A$51:$A$138,0),FALSE) -> -0.0063523943 | W4: =+HLOOKUP($R4,$A$51:$P$138,MATCH(W$2,$A$51:$A$138,0),FALSE) -> -0.0052347698 | X4: =+HLOOKUP($R4,$A$51:$P$138,MATCH(X$2,$A$51:$A$138,0),FALSE) -> -0.0043377015 | Y4: =+HLOOKUP($R4,$A$51:$P$138,MATCH(Y$2,$A$51:$A$138,0),FALSE) -> -0.0042190223 | Z4: =+HLOOKUP($R4,$A$51:$P$138,MATCH(Z$2,$A$51:$A$138,0),FALSE) -> -0.0076333241 | ... AE4: =+HLOOKUP($R4,$A$51:$P$138,MATCH(AE$2,$A$51:$A$138,0),FALSE) -> 0.0033796296
A5: 45108 | B5: ='A.2.2'!B178+'A.2.2'!C178 -> 330.064 | C5: ='A.2.2'!D178 -> 93.232 | D5: ='A.2.2'!E178 -> 1196.922 | E5: ='A.2.2'!F178 -> 76.089 | F5: ='A.2.2'!G178 -> 468.523 | G5: ='A.2.2'!H178 -> 1224.466 | H5: ='A.2.2'!I178 -> 288.833 | I5: ='A.2.2'!J178 -> 530.623 | J5: ='A.2.2'!K178 -> 152.727 | ... O5: ='A.2.2'!P178 -> 0.176 | P5: =SUM(B5:O5) -> 6404.813 | R5: Industria | S5: =+HLOOKUP($R5,$A$51:$P$138,MATCH(S$2,$A$51:$A$138,0),FALSE) -> -0.0012640289 | T5: =+HLOOKUP($R5,$A$51:$P$138,MATCH(T$2,$A$51:$A$138,0),FALSE) -> -0.0025019644 | U5: =+HLOOKUP($R5,$A$51:$P$138,MATCH(U$2,$A$51:$A$138,0),FALSE) -> -0.0034185997 | V5: =+HLOOKUP($R5,$A$51:$P$138,MATCH(V$2,$A$51:$A$138,0),FALSE) -> -0.0030949207 | W5: =+HLOOKUP($R5,$A$51:$P$138,MATCH(W$2,$A$51:$A$138,0),FALSE) -> -0.0042399294 | X5: =+HLOOKUP($R5,$A$51:$P$138,MATCH(X$2,$A$51:$A$138,0),FALSE) -> -0.0050035883 | Y5: =+HLOOKUP($R5,$A$51:$P$138,MATCH(Y$2,$A$51:$A$138,0),FALSE) -> -0.0048901107 | Z5: =+HLOOKUP($R5,$A$51:$P$138,MATCH(Z$2,$A$51:$A$138,0),FALSE) -> -0.0044653171 | ... AE5: =+HLOOKUP($R5,$A$51:$P$138,MATCH(AE$2,$A$51:$A$138,0),FALSE) -> -0.0028402957
A6: 45139 | B6: ='A.2.2'!B179+'A.2.2'!C179 -> 330.037 | C6: ='A.2.2'!D179 -> 93.728 | D6: ='A.2.2'!E179 -> 1198.014 | E6: ='A.2.2'!F179 -> 76.279 | F6: ='A.2.2'!G179 -> 465.01 | G6: ='A.2.2'!H179 -> 1228.656 | H6: ='A.2.2'!I179 -> 288.807 | I6: ='A.2.2'!J179 -> 530.935 | J6: ='A.2.2'!K179 -> 152.476 | ... O6: ='A.2.2'!P179 -> 0.163 | P6: =SUM(B6:O6) -> 6408.136 | R6: EGA | S6: =+HLOOKUP($R6,$A$51:$P$138,MATCH(S$2,$A$51:$A$138,0),FALSE) -> 0.0037503948 | T6: =+HLOOKUP($R6,$A$51:$P$138,MATCH(T$2,$A$51:$A$138,0),FALSE) -> -0.00014421123 | U6: =+HLOOKUP($R6,$A$51:$P$138,MATCH(U$2,$A$51:$A$138,0),FALSE) -> -7.8672016e-05 | V6: =+HLOOKUP($R6,$A$51:$P$138,MATCH(V$2,$A$51:$A$138,0),FALSE) -> 0.0014293207 | W6: =+HLOOKUP($R6,$A$51:$P$138,MATCH(W$2,$A$51:$A$138,0),FALSE) -> 0.0009296966 | X6: =+HLOOKUP($R6,$A$51:$P$138,MATCH(X$2,$A$51:$A$138,0),FALSE) -> -7.8492936e-05 | Y6: =+HLOOKUP($R6,$A$51:$P$138,MATCH(Y$2,$A$51:$A$138,0),FALSE) -> -0.00014391501 | Z6: =+HLOOKUP($R6,$A$51:$P$138,MATCH(Z$2,$A$51:$A$138,0),FALSE) -> -7.8510396e-05 | ... AE6: =+HLOOKUP($R6,$A$51:$P$138,MATCH(AE$2,$A$51:$A$138,0),FALSE) -> 0.00057656524
A7: 45170 | B7: ='A.2.2'!B180+'A.2.2'!C180 -> 325.82 | C7: ='A.2.2'!D180 -> 93.921 | D7: ='A.2.2'!E180 -> 1196.233 | E7: ='A.2.2'!F180 -> 76.485 | F7: ='A.2.2'!G180 -> 458.539 | G7: ='A.2.2'!H180 -> 1229.838 | H7: ='A.2.2'!I180 -> 288.316 | I7: ='A.2.2'!J180 -> 531.368 | J7: ='A.2.2'!K180 -> 152.37 | ... O7: ='A.2.2'!P180 -> 0.153 | P7: =SUM(B7:O7) -> 6393.259 | R7: Construcción | S7: =+HLOOKUP($R7,$A$51:$P$138,MATCH(S$2,$A$51:$A$138,0),FALSE) -> -0.00024755669 | T7: =+HLOOKUP($R7,$A$51:$P$138,MATCH(T$2,$A$51:$A$138,0),FALSE) -> -0.00081661253 | U7: =+HLOOKUP($R7,$A$51:$P$138,MATCH(U$2,$A$51:$A$138,0),FALSE) -> 0.00017663792 | V7: =+HLOOKUP($R7,$A$51:$P$138,MATCH(V$2,$A$51:$A$138,0),FALSE) -> -0.002778261 | W7: =+HLOOKUP($R7,$A$51:$P$138,MATCH(W$2,$A$51:$A$138,0),FALSE) -> -0.0034600338 | X7: =+HLOOKUP($R7,$A$51:$P$138,MATCH(X$2,$A$51:$A$138,0),FALSE) -> -0.0011166783 | Y7: =+HLOOKUP($R7,$A$51:$P$138,MATCH(Y$2,$A$51:$A$138,0),FALSE) -> -0.0026102658 | Z7: =+HLOOKUP($R7,$A$51:$P$138,MATCH(Z$2,$A$51:$A$138,0),FALSE) -> 0.0043343175 | ... AE7: =+HLOOKUP($R7,$A$51:$P$138,MATCH(AE$2,$A$51:$A$138,0),FALSE) -> -0.0052343076
A8: 45200 | B8: ='A.2.2'!B181+'A.2.2'!C181 -> 323.318 | C8: ='A.2.2'!D181 -> 94.247 | D8: ='A.2.2'!E181 -> 1196.018 | E8: ='A.2.2'!F181 -> 76.786 | F8: ='A.2.2'!G181 -> 449.372 | G8: ='A.2.2'!H181 -> 1231.919 | H8: ='A.2.2'!I181 -> 288.076 | I8: ='A.2.2'!J181 -> 529.668 | J8: ='A.2.2'!K181 -> 152.351 | ... O8: ='A.2.2'!P181 -> 0.156 | P8: =SUM(B8:O8) -> 6380.831 | R8: Comercio | S8: =+HLOOKUP($R8,$A$51:$P$138,MATCH(S$2,$A$51:$A$138,0),FALSE) -> 0.0019174791 | T8: =+HLOOKUP($R8,$A$51:$P$138,MATCH(T$2,$A$51:$A$138,0),FALSE) -> -0.00080159143 | U8: =+HLOOKUP($R8,$A$51:$P$138,MATCH(U$2,$A$51:$A$138,0),FALSE) -> -0.0011616101 | V8: =+HLOOKUP($R8,$A$51:$P$138,MATCH(V$2,$A$51:$A$138,0),FALSE) -> -0.001619071 | W8: =+HLOOKUP($R8,$A$51:$P$138,MATCH(W$2,$A$51:$A$138,0),FALSE) -> -0.0030655966 | X8: =+HLOOKUP($R8,$A$51:$P$138,MATCH(X$2,$A$51:$A$138,0),FALSE) -> -0.0033381398 | Y8: =+HLOOKUP($R8,$A$51:$P$138,MATCH(Y$2,$A$51:$A$138,0),FALSE) -> -0.0042159389 | Z8: =+HLOOKUP($R8,$A$51:$P$138,MATCH(Z$2,$A$51:$A$138,0),FALSE) -> -0.0029452791 | ... AE8: =+HLOOKUP($R8,$A$51:$P$138,MATCH(AE$2,$A$51:$A$138,0),FALSE) -> -0.0034433562
A9: 45231 | B9: ='A.2.2'!B182+'A.2.2'!C182 -> 322.278 | C9: ='A.2.2'!D182 -> 94.639 | D9: ='A.2.2'!E182 -> 1193.908 | E9: ='A.2.2'!F182 -> 76.981 | F9: ='A.2.2'!G182 -> 440.941 | G9: ='A.2.2'!H182 -> 1233.221 | H9: ='A.2.2'!I182 -> 287.75 | I9: ='A.2.2'!J182 -> 529.39 | J9: ='A.2.2'!K182 -> 152.086 | ... O9: ='A.2.2'!P182 -> 0.144 | P9: =SUM(B9:O9) -> 6372.697 | R9: Hoteles y restaurantes | S9: =+HLOOKUP($R9,$A$51:$P$138,MATCH(S$2,$A$51:$A$138,0),FALSE) -> 0.0026223589 | T9: =+HLOOKUP($R9,$A$51:$P$138,MATCH(T$2,$A$51:$A$138,0),FALSE) -> -0.0015799756 | U9: =+HLOOKUP($R9,$A$51:$P$138,MATCH(U$2,$A$51:$A$138,0),FALSE) -> -0.0034429542 | V9: =+HLOOKUP($R9,$A$51:$P$138,MATCH(V$2,$A$51:$A$138,0),FALSE) -> 4.291738e-05 | W9: =+HLOOKUP($R9,$A$51:$P$138,MATCH(W$2,$A$51:$A$138,0),FALSE) -> -0.00095844703 | X9: =+HLOOKUP($R9,$A$51:$P$138,MATCH(X$2,$A$51:$A$138,0),FALSE) -> -0.0017862832 | Y9: =+HLOOKUP($R9,$A$51:$P$138,MATCH(Y$2,$A$51:$A$138,0),FALSE) -> 0.00073874313 | Z9: =+HLOOKUP($R9,$A$51:$P$138,MATCH(Z$2,$A$51:$A$138,0),FALSE) -> -0.0046621133 | ... AE9: =+HLOOKUP($R9,$A$51:$P$138,MATCH(AE$2,$A$51:$A$138,0),FALSE) -> -0.0014319981
A10: 45261 | B10: ='A.2.2'!B183+'A.2.2'!C183 -> 327.685 | C10: ='A.2.2'!D183 -> 94.995 | D10: ='A.2.2'!E183 -> 1192.108 | E10: ='A.2.2'!F183 -> 77.068 | F10: ='A.2.2'!G183 -> 427.241 | G10: ='A.2.2'!H183 -> 1234.486 | H10: ='A.2.2'!I183 -> 287.239 | I10: ='A.2.2'!J183 -> 528.91 | J10: ='A.2.2'!K183 -> 152.109 | ... O10: ='A.2.2'!P183 -> 0.145 | P10: =SUM(B10:O10) -> 6361.318 | R10: Transporte | S10: =+HLOOKUP($R10,$A$51:$P$138,MATCH(S$2,$A$51:$A$138,0),FALSE) -> 0.0030888659 | T10: =+HLOOKUP($R10,$A$51:$P$138,MATCH(T$2,$A$51:$A$138,0),FALSE) -> -0.0055269965 | U10: =+HLOOKUP($R10,$A$51:$P$138,MATCH(U$2,$A$51:$A$138,0),FALSE) -> -0.00054586425 | V10: =+HLOOKUP($R10,$A$51:$P$138,MATCH(V$2,$A$51:$A$138,0),FALSE) -> -9.9125557e-05 | W10: =+HLOOKUP($R10,$A$51:$P$138,MATCH(W$2,$A$51:$A$138,0),FALSE) -> -0.0021945853 | X10: =+HLOOKUP($R10,$A$51:$P$138,MATCH(X$2,$A$51:$A$138,0),FALSE) -> -0.0013402972 | Y10: =+HLOOKUP($R10,$A$51:$P$138,MATCH(Y$2,$A$51:$A$138,0),FALSE) -> -0.0022628362 | Z10: =+HLOOKUP($R10,$A$51:$P$138,MATCH(Z$2,$A$51:$A$138,0),FALSE) -> -0.0013197229 | ... AE10: =+HLOOKUP($R10,$A$51:$P$138,MATCH(AE$2,$A$51:$A$138,0),FALSE) -> -0.0033556117
A11: 45292 | B11: ='A.2.2'!B184+'A.2.2'!C184 -> 332.003 | C11: ='A.2.2'!D184 -> 95.338 | D11: ='A.2.2'!E184 -> 1188.647 | E11: ='A.2.2'!F184 -> 77.176 | F11: ='A.2.2'!G184 -> 407.041 | G11: ='A.2.2'!H184 -> 1231.14 | H11: ='A.2.2'!I184 -> 284.027 | I11: ='A.2.2'!J184 -> 527.248 | J11: ='A.2.2'!K184 -> 152.03 | ... O11: ='A.2.2'!P184 -> 0.142 | P11: =SUM(B11:O11) -> 6326.652 | R11: Intermediación Financiera | S11: =+HLOOKUP($R11,$A$51:$P$138,MATCH(S$2,$A$51:$A$138,0),FALSE) -> -0.0024273776 | T11: =+HLOOKUP($R11,$A$51:$P$138,MATCH(T$2,$A$51:$A$138,0),FALSE) -> -0.0040687702 | U11: =+HLOOKUP($R11,$A$51:$P$138,MATCH(U$2,$A$51:$A$138,0),FALSE) -> -0.00048730992 | V11: =+HLOOKUP($R11,$A$51:$P$138,MATCH(V$2,$A$51:$A$138,0),FALSE) -> -0.0055700632 | W11: =+HLOOKUP($R11,$A$51:$P$138,MATCH(W$2,$A$51:$A$138,0),FALSE) -> -0.0017260486 | X11: =+HLOOKUP($R11,$A$51:$P$138,MATCH(X$2,$A$51:$A$138,0),FALSE) -> -0.0027785627 | Y11: =+HLOOKUP($R11,$A$51:$P$138,MATCH(Y$2,$A$51:$A$138,0),FALSE) -> -0.0025704166 | Z11: =+HLOOKUP($R11,$A$51:$P$138,MATCH(Z$2,$A$51:$A$138,0),FALSE) -> -0.0044438733 | ... AE11: =+HLOOKUP($R11,$A$51:$P$138,MATCH(AE$2,$A$51:$A$138,0),FALSE) -> -0.002086376
A12: 45323 | B12: ='A.2.2'!B185+'A.2.2'!C185 -> 333.523 | C12: ='A.2.2'!D185 -> 95.635 | D12: ='A.2.2'!E185 -> 1185.455 | E12: ='A.2.2'!F185 -> 77.144 | F12: ='A.2.2'!G185 -> 394.359 | G12: ='A.2.2'!H185 -> 1229.552 | H12: ='A.2.2'!I185 -> 283.554 | I12: ='A.2.2'!J185 -> 525.056 | J12: ='A.2.2'!K185 -> 151.838 | ... O12: ='A.2.2'!P185 -> 0.135 | P12: =SUM(B12:O12) -> 6300.738 | R12: Servicios Inmobiliarios | S12: =+HLOOKUP($R12,$A$51:$P$138,MATCH(S$2,$A$51:$A$138,0),FALSE) -> 0.0012915916 | T12: =+HLOOKUP($R12,$A$51:$P$138,MATCH(T$2,$A$51:$A$138,0),FALSE) -> -0.0038809255 | U12: =+HLOOKUP($R12,$A$51:$P$138,MATCH(U$2,$A$51:$A$138,0),FALSE) -> -0.0040572151 | V12: =+HLOOKUP($R12,$A$51:$P$138,MATCH(V$2,$A$51:$A$138,0),FALSE) -> -0.0030578359 | W12: =+HLOOKUP($R12,$A$51:$P$138,MATCH(W$2,$A$51:$A$138,0),FALSE) -> -0.00049147583 | X12: =+HLOOKUP($R12,$A$51:$P$138,MATCH(X$2,$A$51:$A$138,0),FALSE) -> -0.0025476831 | Y12: =+HLOOKUP($R12,$A$51:$P$138,MATCH(Y$2,$A$51:$A$138,0),FALSE) -> -0.0035503133 | Z12: =+HLOOKUP($R12,$A$51:$P$138,MATCH(Z$2,$A$51:$A$138,0),FALSE) -> -0.0020129606 | ... AE12: =+HLOOKUP($R12,$A$51:$P$138,MATCH(AE$2,$A$51:$A$138,0),FALSE) -> 0.00080062045
A13: 45352 | B13: ='A.2.2'!B186+'A.2.2'!C186 -> 332.565 | C13: ='A.2.2'!D186 -> 95.835 | D13: ='A.2.2'!E186 -> 1181.797 | E13: ='A.2.2'!F186 -> 77.062 | F13: ='A.2.2'!G186 -> 384.136 | G13: ='A.2.2'!H186 -> 1227.72 | H13: ='A.2.2'!I186 -> 283.487 | I13: ='A.2.2'!J186 -> 523.186 | J13: ='A.2.2'!K186 -> 151.699 | ... O13: ='A.2.2'!P186 -> 0.123 | P13: =SUM(B13:O13) -> 6275.855 | R13: Educación | S13: =+HLOOKUP($R13,$A$51:$P$138,MATCH(S$2,$A$51:$A$138,0),FALSE) -> 0.00097404133 | T13: =+HLOOKUP($R13,$A$51:$P$138,MATCH(T$2,$A$51:$A$138,0),FALSE) -> 0.0013132038 | U13: =+HLOOKUP($R13,$A$51:$P$138,MATCH(U$2,$A$51:$A$138,0),FALSE) -> -0.00022172531 | V13: =+HLOOKUP($R13,$A$51:$P$138,MATCH(V$2,$A$51:$A$138,0),FALSE) -> -0.00074789904 | W13: =+HLOOKUP($R13,$A$51:$P$138,MATCH(W$2,$A$51:$A$138,0),FALSE) -> 0.0001062481 | X13: =+HLOOKUP($R13,$A$51:$P$138,MATCH(X$2,$A$51:$A$138,0),FALSE) -> 0.00043675133 | Y13: =+HLOOKUP($R13,$A$51:$P$138,MATCH(Y$2,$A$51:$A$138,0),FALSE) -> -0.00099819004 | Z13: =+HLOOKUP($R13,$A$51:$P$138,MATCH(Z$2,$A$51:$A$138,0),FALSE) -> 0.0012070562 | ... AE13: =+HLOOKUP($R13,$A$51:$P$138,MATCH(AE$2,$A$51:$A$138,0),FALSE) -> -0.00085346762
A14: 45383 | B14: ='A.2.2'!B187+'A.2.2'!C187 -> 333.345 | C14: ='A.2.2'!D187 -> 95.633 | D14: ='A.2.2'!E187 -> 1177.019 | E14: ='A.2.2'!F187 -> 76.805 | F14: ='A.2.2'!G187 -> 376.403 | G14: ='A.2.2'!H187 -> 1227.066 | H14: ='A.2.2'!I187 -> 283.331 | I14: ='A.2.2'!J187 -> 522.527 | J14: ='A.2.2'!K187 -> 151.652 | ... O14: ='A.2.2'!P187 -> 0.106 | P14: =SUM(B14:O14) -> 6258.796 | R14: Salud | S14: =+HLOOKUP($R14,$A$51:$P$138,MATCH(S$2,$A$51:$A$138,0),FALSE) -> 0.00021801995 | T14: =+HLOOKUP($R14,$A$51:$P$138,MATCH(T$2,$A$51:$A$138,0),FALSE) -> 0.00031787646 | U14: =+HLOOKUP($R14,$A$51:$P$138,MATCH(U$2,$A$51:$A$138,0),FALSE) -> -0.00029053756 | V14: =+HLOOKUP($R14,$A$51:$P$138,MATCH(V$2,$A$51:$A$138,0),FALSE) -> -0.00023613037 | W14: =+HLOOKUP($R14,$A$51:$P$138,MATCH(W$2,$A$51:$A$138,0),FALSE) -> -0.00022407403 | X14: =+HLOOKUP($R14,$A$51:$P$138,MATCH(X$2,$A$51:$A$138,0),FALSE) -> -0.00023623907 | Y14: =+HLOOKUP($R14,$A$51:$P$138,MATCH(Y$2,$A$51:$A$138,0),FALSE) -> -0.00043017789 | Z14: =+HLOOKUP($R14,$A$51:$P$138,MATCH(Z$2,$A$51:$A$138,0),FALSE) -> 0.00028791892 | ... AE14: =+HLOOKUP($R14,$A$51:$P$138,MATCH(AE$2,$A$51:$A$138,0),FALSE) -> 0.00074586816
... A16: 45444 | B16: ='A.2.2'!B189+'A.2.2'!C189 -> 335.72 | C16: ='A.2.2'!D189 -> 95.893 | D16: ='A.2.2'!E189 -> 1167.788 | E16: ='A.2.2'!F189 -> 76.189 | F16: ='A.2.2'!G189 -> 372.784 | G16: ='A.2.2'!H189 -> 1227.579 | H16: ='A.2.2'!I189 -> 281.535 | I16: ='A.2.2'!J189 -> 520.375 | J16: ='A.2.2'!K189 -> 151.712 | ... O16: ='A.2.2'!P189 -> 0.102 | P16: =SUM(B16:O16) -> 6239.26 | R16: Total | S16: =+HLOOKUP($R16,$A$51:$P$138,MATCH(S$2,$A$51:$A$138,0),FALSE) -> 0.00035819666 | T16: =+HLOOKUP($R16,$A$51:$P$138,MATCH(T$2,$A$51:$A$138,0),FALSE) -> -0.0023250511 | U16: =+HLOOKUP($R16,$A$51:$P$138,MATCH(U$2,$A$51:$A$138,0),FALSE) -> -0.0019373398 | V16: =+HLOOKUP($R16,$A$51:$P$138,MATCH(V$2,$A$51:$A$138,0),FALSE) -> -0.0017364619 | W16: =+HLOOKUP($R16,$A$51:$P$138,MATCH(W$2,$A$51:$A$138,0),FALSE) -> -0.0020531544 | X16: =+HLOOKUP($R16,$A$51:$P$138,MATCH(X$2,$A$51:$A$138,0),FALSE) -> -0.0025293369 | Y16: =+HLOOKUP($R16,$A$51:$P$138,MATCH(Y$2,$A$51:$A$138,0),FALSE) -> -0.0026542814 | Z16: =+HLOOKUP($R16,$A$51:$P$138,MATCH(Z$2,$A$51:$A$138,0),FALSE) -> -0.0020456091 | ... AE16: =+HLOOKUP($R16,$A$51:$P$138,MATCH(AE$2,$A$51:$A$138,0),FALSE) -> -0.0014752678
A17: 45474 | B17: ='A.2.2'!B190+'A.2.2'!C190 -> 334.454 | C17: ='A.2.2'!D190 -> 95.727 | D17: ='A.2.2'!E190 -> 1165.849 | E17: ='A.2.2'!F190 -> 76.18 | F17: ='A.2.2'!G190 -> 371.823 | G17: ='A.2.2'!H190 -> 1228.423 | H17: ='A.2.2'!I190 -> 281.063 | I17: ='A.2.2'!J190 -> 520.084 | J17: ='A.2.2'!K190 -> 151.45 | ... O17: ='A.2.2'!P190 -> 0.091 | P17: =SUM(B17:O17) -> 6233.118
A18: 45505 | B18: ='A.2.2'!B191+'A.2.2'!C191 -> 335.769 | C18: ='A.2.2'!D191 -> 95.526 | D18: ='A.2.2'!E191 -> 1165.812 | E18: ='A.2.2'!F191 -> 75.881 | F18: ='A.2.2'!G191 -> 372.688 | G18: ='A.2.2'!H191 -> 1232.053 | H18: ='A.2.2'!I191 -> 280.385 | I18: ='A.2.2'!J191 -> 519.196 | J18: ='A.2.2'!K191 -> 151.831 | ... O18: ='A.2.2'!P191 -> 0.086 | P18: =SUM(B18:O18) -> 6237.229 | R18: Variación mensual en miles
A19: 45536 | B19: ='A.2.2'!B192+'A.2.2'!C192 -> 335.741 | C19: ='A.2.2'!D192 -> 95.441 | D19: ='A.2.2'!E192 -> 1167.398 | E19: ='A.2.2'!F192 -> 75.909 | F19: ='A.2.2'!G192 -> 373.921 | G19: ='A.2.2'!H192 -> 1237.094 | H19: ='A.2.2'!I192 -> 280.254 | I19: ='A.2.2'!J192 -> 518.715 | J19: ='A.2.2'!K192 -> 151.657 | ... O19: ='A.2.2'!P192 -> 0.093 | P19: =SUM(B19:O19) -> 6246.337 | S19: =A21 -> 45597 | T19: =A22 -> 45627 | U19: =A23 -> 45658 | V19: =A24 -> 45689 | W19: =A25 -> 45717 | X19: =A26 -> 45748 | Y19: =A27 -> 45778 | Z19: =A28 -> 45809 | AA19: =A29 -> 45839 | AB19: =A30 -> 45870 | AC19: =A31 -> 45901 | AD19: =A32 -> 45931 | AE19: =A33 -> 45962
A20: 45566 | B20: ='A.2.2'!B193+'A.2.2'!C193 -> 336.16 | C20: ='A.2.2'!D193 -> 95.194 | D20: ='A.2.2'!E193 -> 1169.927 | E20: ='A.2.2'!F193 -> 75.884 | F20: ='A.2.2'!G193 -> 372.544 | G20: ='A.2.2'!H193 -> 1241.625 | H20: ='A.2.2'!I193 -> 280.371 | I20: ='A.2.2'!J193 -> 518.4 | J20: ='A.2.2'!K193 -> 151.521 | ... O20: ='A.2.2'!P193 -> 0.081 | P20: =SUM(B20:O20) -> 6253.879 | R20: Agro y Pesca | S20: =$B$111 -> 0.124 | T20: =$B$112 -> 0.229 | U20: =$B$113 -> -1.145 | V20: =$B$114 -> -0.765 | W20: =$B$115 -> -3.85 | X20: =$B$116 -> 4.275 | Y20: =$B$117 -> -0.956 | Z20: =$B$118 -> -1.205 | AA20: =$B$119 -> 0.267 | AB20: =$B$122 -> -0.948 | AC20: =$B123 -> 0.447 | AD20: =$B124 -> -0.394 | AE20: =$B125 -> -0.258
A21: 45597 | B21: ='A.2.2'!B194+'A.2.2'!C194 -> 336.284 | C21: ='A.2.2'!D194 -> 94.772 | D21: ='A.2.2'!E194 -> 1168.927 | E21: ='A.2.2'!F194 -> 75.96 | F21: ='A.2.2'!G194 -> 373.123 | G21: ='A.2.2'!H194 -> 1246.004 | H21: ='A.2.2'!I194 -> 279.765 | I21: ='A.2.2'!J194 -> 518.177 | J21: ='A.2.2'!K194 -> 151.404 | ... O21: ='A.2.2'!P194 -> 0.086 | P21: =SUM(B21:O21) -> 6255.158 | R21: Minería | S21: =$C$111 -> -0.422 | T21: =$C$112 -> -0.393 | U21: =$C$113 -> -0.351 | V21: =$C$114 -> -1.156 | W21: =$C$115 -> -1.107 | X21: =$C$116 -> -0.641 | Y21: =$C$117 -> -0.929 | Z21: =$C$118 -> -0.931 | AA21: =$C$119 -> -0.636 | AB21: =$C$122 -> -0.38 | AC21: =$C$123 -> -0.368 | AD21: =$C$124 -> -0.663 | AE21: =$C$125 -> -0.197
A22: 45627 | B22: ='A.2.2'!B195+'A.2.2'!C195 -> 336.513 | C22: ='A.2.2'!D195 -> 94.379 | D22: ='A.2.2'!E195 -> 1167.137 | E22: ='A.2.2'!F195 -> 75.962 | F22: ='A.2.2'!G195 -> 376.615 | G22: ='A.2.2'!H195 -> 1249.97 | H22: ='A.2.2'!I195 -> 279.782 | I22: ='A.2.2'!J195 -> 516.72 | J22: ='A.2.2'!K195 -> 151.41 | ... O22: ='A.2.2'!P195 -> 0.086 | P22: =SUM(B22:O22) -> 6263.756 | R22: Industria | S22: =$D$111 -> -1 | T22: =$D$112 -> -1.79 | U22: =$D$113 -> -0.133 | V22: =$D$114 -> -0.504 | W22: =$D$115 -> -2.759 | X22: =$D$116 -> -1.584 | Y22: =$D$117 -> -1.469 | Z22: =$D$118 -> -2.904 | AA22: =$D$119 -> -3.958 | AB22: =$D$122 -> -5.731 | AC22: =$D$123 -> -5.573 | AD22: =$D$124 -> -5.064 | AE22: =$D$125 -> -4.448
A23: 45658 | B23: ='A.2.2'!B196+'A.2.2'!C196 -> 335.368 | C23: ='A.2.2'!D196 -> 94.028 | D23: ='A.2.2'!E196 -> 1167.004 | E23: ='A.2.2'!F196 -> 75.943 | F23: ='A.2.2'!G196 -> 378.657 | G23: ='A.2.2'!H196 -> 1250.299 | H23: ='A.2.2'!I196 -> 277.9 | I23: ='A.2.2'!J196 -> 515.585 | J23: ='A.2.2'!K196 -> 151.138 | ... O23: ='A.2.2'!P196 -> 0.091 | P23: =SUM(B23:O23) -> 6254.669 | R23: EGA | S23: =$E$111 -> 0.076 | T23: =$D$112 -> -1.79 | U23: =$E$113 -> -0.019 | V23: =$E$114 -> 0.055 | W23: =$E$115 -> -0.116 | X23: =$E$116 -> 0.11 | Y23: =$E$117 -> 0.285 | Z23: =$E$118 -> -0.011 | AA23: =$E$119 -> -0.006 | AB23: =$E$122 -> -0.006 | AC23: =$E$123 -> -0.011 | AD23: =$E$124 -> -0.006 | AE23: =$E$125 -> 0.033
A24: 45689 | B24: ='A.2.2'!B197+'A.2.2'!C197 -> 334.603 | C24: ='A.2.2'!D197 -> 92.872 | D24: ='A.2.2'!E197 -> 1166.5 | E24: ='A.2.2'!F197 -> 75.998 | F24: ='A.2.2'!G197 -> 381.054 | G24: ='A.2.2'!H197 -> 1252.513 | H24: ='A.2.2'!I197 -> 279.233 | I24: ='A.2.2'!J197 -> 515.665 | J24: ='A.2.2'!K197 -> 151.091 | ... O24: ='A.2.2'!P197 -> 0.089 | P24: =SUM(B24:O24) -> 6265.325 | R24: Construcción | S24: =$F$111 -> 0.579 | T24: =$F$112 -> 3.492 | U24: =$F$113 -> 2.042 | V24: =$F$114 -> 2.397 | W24: =$F$115 -> -3.144 | X24: =$F$116 -> 1.801 | Y24: =$F$117 -> -0.094 | Z24: =$F$118 -> -0.31 | AA24: =$F$119 -> 0.067 | AB24: =$F$122 -> -0.421 | AC24: =$F$123 -> -0.983 | AD24: =$F$124 -> 1.628 | AE24: =$F$125 -> 3.487
